Traceback (most recent call last):
  File "/home/richard/.virtualenvs/etcdocs/lib/python3.8/site-packages/jupyter_cache/executors/utils.py", line 51, in single_nb_execution
    executenb(
  File "/home/richard/.virtualenvs/etcdocs/lib/python3.8/site-packages/nbclient/client.py", line 1087, in execute
    return NotebookClient(nb=nb, resources=resources, km=km, **kwargs).execute()
  File "/home/richard/.virtualenvs/etcdocs/lib/python3.8/site-packages/nbclient/util.py", line 74, in wrapped
    return just_run(coro(*args, **kwargs))
  File "/home/richard/.virtualenvs/etcdocs/lib/python3.8/site-packages/nbclient/util.py", line 53, in just_run
    return loop.run_until_complete(coro)
  File "/usr/lib/python3.8/asyncio/base_events.py", line 616, in run_until_complete
    return future.result()
  File "/home/richard/.virtualenvs/etcdocs/lib/python3.8/site-packages/nbclient/client.py", line 540, in async_execute
    await self.async_execute_cell(
  File "/home/richard/.virtualenvs/etcdocs/lib/python3.8/site-packages/nbclient/client.py", line 832, in async_execute_cell
    self._check_raise_for_error(cell, exec_reply)
  File "/home/richard/.virtualenvs/etcdocs/lib/python3.8/site-packages/nbclient/client.py", line 740, in _check_raise_for_error
    raise CellExecutionError.from_cell_and_msg(cell, exec_reply['content'])
nbclient.exceptions.CellExecutionError: An error occurred while executing the following cell:
------------------
import glob
import pandas as pd

df = pd.concat(map(pd.read_csv, glob.glob('/home/richard/Git/metadata/vam-metadata/data/*.csv')))
------------------

[0;31m---------------------------------------------------------------------------[0m
[0;31mValueError[0m                                Traceback (most recent call last)
[0;32m<ipython-input-2-d941a58cf21c>[0m in [0;36m<module>[0;34m[0m
[1;32m      2[0m [0;32mimport[0m [0mpandas[0m [0;32mas[0m [0mpd[0m[0;34m[0m[0;34m[0m[0m
[1;32m      3[0m [0;34m[0m[0m
[0;32m----> 4[0;31m [0mdf[0m [0;34m=[0m [0mpd[0m[0;34m.[0m[0mconcat[0m[0;34m([0m[0mmap[0m[0;34m([0m[0mpd[0m[0;34m.[0m[0mread_csv[0m[0;34m,[0m [0mglob[0m[0;34m.[0m[0mglob[0m[0;34m([0m[0;34m'/home/richard/Git/metadata/vam-metadata/data/*.csv'[0m[0;34m)[0m[0;34m)[0m[0;34m)[0m[0;34m[0m[0;34m[0m[0m
[0m
[0;32m~/.virtualenvs/etcdocs/lib/python3.8/site-packages/pandas/core/reshape/concat.py[0m in [0;36mconcat[0;34m(objs, axis, join, ignore_index, keys, levels, names, verify_integrity, sort, copy)[0m
[1;32m    272[0m     [0mValueError[0m[0;34m:[0m [0mIndexes[0m [0mhave[0m [0moverlapping[0m [0mvalues[0m[0;34m:[0m [0;34m[[0m[0;34m'a'[0m[0;34m][0m[0;34m[0m[0;34m[0m[0m
[1;32m    273[0m     """
[0;32m--> 274[0;31m     op = _Concatenator(
[0m[1;32m    275[0m         [0mobjs[0m[0;34m,[0m[0;34m[0m[0;34m[0m[0m
[1;32m    276[0m         [0maxis[0m[0;34m=[0m[0maxis[0m[0;34m,[0m[0;34m[0m[0;34m[0m[0m

[0;32m~/.virtualenvs/etcdocs/lib/python3.8/site-packages/pandas/core/reshape/concat.py[0m in [0;36m__init__[0;34m(self, objs, axis, join, keys, levels, names, ignore_index, verify_integrity, copy, sort)[0m
[1;32m    329[0m [0;34m[0m[0m
[1;32m    330[0m         [0;32mif[0m [0mlen[0m[0;34m([0m[0mobjs[0m[0;34m)[0m [0;34m==[0m [0;36m0[0m[0;34m:[0m[0;34m[0m[0;34m[0m[0m
[0;32m--> 331[0;31m             [0;32mraise[0m [0mValueError[0m[0;34m([0m[0;34m"No objects to concatenate"[0m[0;34m)[0m[0;34m[0m[0;34m[0m[0m
[0m[1;32m    332[0m [0;34m[0m[0m
[1;32m    333[0m         [0;32mif[0m [0mkeys[0m [0;32mis[0m [0;32mNone[0m[0;34m:[0m[0;34m[0m[0;34m[0m[0m

[0;31mValueError[0m: No objects to concatenate
ValueError: No objects to concatenate

